<?xml version="1.0" encoding="UTF-8"?>
<testng-results skipped="4" failed="10" ignored="0" total="23" passed="9">
  <reporter-output>
  </reporter-output>
  <suite name="restassuredtestsuite" duration-ms="10278" started-at="2021-04-08T19:51:40 IST" finished-at="2021-04-08T19:51:50 IST">
    <groups>
    </groups>
    <test name="restassuredtests" duration-ms="10278" started-at="2021-04-08T19:51:40 IST" finished-at="2021-04-08T19:51:50 IST">
      <class name="com.employee.testCases.TC005_Delete_Employee_Record">
        <test-method status="PASS" signature="setUp()[pri:0, instance:com.employee.testCases.TC005_Delete_Employee_Record@4d1b0d2a]" name="setUp" is-config="true" duration-ms="36" started-at="2021-04-08T19:51:40 IST" finished-at="2021-04-08T19:51:40 IST">
          <reporter-output>
          </reporter-output>
        </test-method> <!-- setUp -->
        <test-method status="FAIL" signature="getAllEmployees()[pri:0, instance:com.employee.testCases.TC005_Delete_Employee_Record@4d1b0d2a]" name="getAllEmployees" is-config="true" duration-ms="3879" started-at="2021-04-08T19:51:40 IST" finished-at="2021-04-08T19:51:44 IST">
          <exception class="io.restassured.path.json.exception.JsonPathException">
            <message>
              <![CDATA[Failed to parse the JSON document]]>
            </message>
            <full-stacktrace>
              <![CDATA[io.restassured.path.json.exception.JsonPathException: Failed to parse the JSON document
at io.restassured.path.json.JsonPath$ExceptionCatcher.invoke(JsonPath.java:1002)
at io.restassured.path.json.JsonPath$4.doParseWith(JsonPath.java:967)
at io.restassured.path.json.JsonPath$JsonParser.parseWith(JsonPath.java:1047)
at io.restassured.path.json.JsonPath.get(JsonPath.java:202)
at com.employee.testCases.TC005_Delete_Employee_Record.getAllEmployees(TC005_Delete_Employee_Record.java:28)
at sun.reflect.NativeMethodAccessorImpl.invoke0(Native Method)
at sun.reflect.NativeMethodAccessorImpl.invoke(Unknown Source)
at sun.reflect.DelegatingMethodAccessorImpl.invoke(Unknown Source)
at java.lang.reflect.Method.invoke(Unknown Source)
at org.testng.internal.MethodInvocationHelper.invokeMethod(MethodInvocationHelper.java:133)
at org.testng.internal.MethodInvocationHelper.invokeMethodConsideringTimeout(MethodInvocationHelper.java:62)
at org.testng.internal.ConfigInvoker.invokeConfigurationMethod(ConfigInvoker.java:385)
at org.testng.internal.ConfigInvoker.invokeConfigurations(ConfigInvoker.java:321)
at org.testng.internal.TestMethodWorker.invokeBeforeClassMethods(TestMethodWorker.java:176)
at org.testng.internal.TestMethodWorker.run(TestMethodWorker.java:122)
at java.util.concurrent.ThreadPoolExecutor.runWorker(Unknown Source)
at java.util.concurrent.ThreadPoolExecutor$Worker.run(Unknown Source)
at java.lang.Thread.run(Unknown Source)
Caused by: java.lang.IllegalArgumentException: The JSON input text should neither be null nor empty.
at sun.reflect.NativeConstructorAccessorImpl.newInstance0(Native Method)
at sun.reflect.NativeConstructorAccessorImpl.newInstance(Unknown Source)
at sun.reflect.DelegatingConstructorAccessorImpl.newInstance(Unknown Source)
at java.lang.reflect.Constructor.newInstance(Unknown Source)
at org.codehaus.groovy.reflection.CachedConstructor.invoke(CachedConstructor.java:72)
at org.codehaus.groovy.runtime.callsite.ConstructorSite$ConstructorSiteNoUnwrapNoCoerce.callConstructor(ConstructorSite.java:105)
at org.codehaus.groovy.runtime.callsite.CallSiteArray.defaultCallConstructor(CallSiteArray.java:59)
at org.codehaus.groovy.runtime.callsite.AbstractCallSite.callConstructor(AbstractCallSite.java:263)
at org.codehaus.groovy.runtime.callsite.AbstractCallSite.callConstructor(AbstractCallSite.java:277)
at io.restassured.internal.path.json.ConfigurableJsonSlurper.parseText(ConfigurableJsonSlurper.groovy:80)
at io.restassured.path.json.JsonPath$4$1.method(JsonPath.java:965)
at io.restassured.path.json.JsonPath$ExceptionCatcher.invoke(JsonPath.java:1000)
... 17 more
]]>
            </full-stacktrace>
          </exception> <!-- io.restassured.path.json.exception.JsonPathException -->
          <reporter-output>
          </reporter-output>
        </test-method> <!-- getAllEmployees -->
        <test-method status="SKIP" signature="checkContentType()[pri:0, instance:com.employee.testCases.TC005_Delete_Employee_Record@4d1b0d2a]" name="checkContentType" duration-ms="0" started-at="2021-04-08T19:51:44 IST" finished-at="2021-04-08T19:51:44 IST">
          <exception class="io.restassured.path.json.exception.JsonPathException">
            <message>
              <![CDATA[Failed to parse the JSON document]]>
            </message>
            <full-stacktrace>
              <![CDATA[io.restassured.path.json.exception.JsonPathException: Failed to parse the JSON document
at io.restassured.path.json.JsonPath$ExceptionCatcher.invoke(JsonPath.java:1002)
at io.restassured.path.json.JsonPath$4.doParseWith(JsonPath.java:967)
at io.restassured.path.json.JsonPath$JsonParser.parseWith(JsonPath.java:1047)
at io.restassured.path.json.JsonPath.get(JsonPath.java:202)
at com.employee.testCases.TC005_Delete_Employee_Record.getAllEmployees(TC005_Delete_Employee_Record.java:28)
at sun.reflect.NativeMethodAccessorImpl.invoke0(Native Method)
at sun.reflect.NativeMethodAccessorImpl.invoke(Unknown Source)
at sun.reflect.DelegatingMethodAccessorImpl.invoke(Unknown Source)
at java.lang.reflect.Method.invoke(Unknown Source)
at org.testng.internal.MethodInvocationHelper.invokeMethod(MethodInvocationHelper.java:133)
at org.testng.internal.MethodInvocationHelper.invokeMethodConsideringTimeout(MethodInvocationHelper.java:62)
at org.testng.internal.ConfigInvoker.invokeConfigurationMethod(ConfigInvoker.java:385)
at org.testng.internal.ConfigInvoker.invokeConfigurations(ConfigInvoker.java:321)
at org.testng.internal.TestMethodWorker.invokeBeforeClassMethods(TestMethodWorker.java:176)
at org.testng.internal.TestMethodWorker.run(TestMethodWorker.java:122)
at java.util.concurrent.ThreadPoolExecutor.runWorker(Unknown Source)
at java.util.concurrent.ThreadPoolExecutor$Worker.run(Unknown Source)
at java.lang.Thread.run(Unknown Source)
Caused by: java.lang.IllegalArgumentException: The JSON input text should neither be null nor empty.
at sun.reflect.NativeConstructorAccessorImpl.newInstance0(Native Method)
at sun.reflect.NativeConstructorAccessorImpl.newInstance(Unknown Source)
at sun.reflect.DelegatingConstructorAccessorImpl.newInstance(Unknown Source)
at java.lang.reflect.Constructor.newInstance(Unknown Source)
at org.codehaus.groovy.reflection.CachedConstructor.invoke(CachedConstructor.java:72)
at org.codehaus.groovy.runtime.callsite.ConstructorSite$ConstructorSiteNoUnwrapNoCoerce.callConstructor(ConstructorSite.java:105)
at org.codehaus.groovy.runtime.callsite.CallSiteArray.defaultCallConstructor(CallSiteArray.java:59)
at org.codehaus.groovy.runtime.callsite.AbstractCallSite.callConstructor(AbstractCallSite.java:263)
at org.codehaus.groovy.runtime.callsite.AbstractCallSite.callConstructor(AbstractCallSite.java:277)
at io.restassured.internal.path.json.ConfigurableJsonSlurper.parseText(ConfigurableJsonSlurper.groovy:80)
at io.restassured.path.json.JsonPath$4$1.method(JsonPath.java:965)
at io.restassured.path.json.JsonPath$ExceptionCatcher.invoke(JsonPath.java:1000)
... 17 more
]]>
            </full-stacktrace>
          </exception> <!-- io.restassured.path.json.exception.JsonPathException -->
          <reporter-output>
          </reporter-output>
        </test-method> <!-- checkContentType -->
        <test-method status="SKIP" signature="checkResponseTime()[pri:0, instance:com.employee.testCases.TC005_Delete_Employee_Record@4d1b0d2a]" name="checkResponseTime" duration-ms="0" started-at="2021-04-08T19:51:44 IST" finished-at="2021-04-08T19:51:44 IST">
          <exception class="io.restassured.path.json.exception.JsonPathException">
            <message>
              <![CDATA[Failed to parse the JSON document]]>
            </message>
            <full-stacktrace>
              <![CDATA[io.restassured.path.json.exception.JsonPathException: Failed to parse the JSON document
at io.restassured.path.json.JsonPath$ExceptionCatcher.invoke(JsonPath.java:1002)
at io.restassured.path.json.JsonPath$4.doParseWith(JsonPath.java:967)
at io.restassured.path.json.JsonPath$JsonParser.parseWith(JsonPath.java:1047)
at io.restassured.path.json.JsonPath.get(JsonPath.java:202)
at com.employee.testCases.TC005_Delete_Employee_Record.getAllEmployees(TC005_Delete_Employee_Record.java:28)
at sun.reflect.NativeMethodAccessorImpl.invoke0(Native Method)
at sun.reflect.NativeMethodAccessorImpl.invoke(Unknown Source)
at sun.reflect.DelegatingMethodAccessorImpl.invoke(Unknown Source)
at java.lang.reflect.Method.invoke(Unknown Source)
at org.testng.internal.MethodInvocationHelper.invokeMethod(MethodInvocationHelper.java:133)
at org.testng.internal.MethodInvocationHelper.invokeMethodConsideringTimeout(MethodInvocationHelper.java:62)
at org.testng.internal.ConfigInvoker.invokeConfigurationMethod(ConfigInvoker.java:385)
at org.testng.internal.ConfigInvoker.invokeConfigurations(ConfigInvoker.java:321)
at org.testng.internal.TestMethodWorker.invokeBeforeClassMethods(TestMethodWorker.java:176)
at org.testng.internal.TestMethodWorker.run(TestMethodWorker.java:122)
at java.util.concurrent.ThreadPoolExecutor.runWorker(Unknown Source)
at java.util.concurrent.ThreadPoolExecutor$Worker.run(Unknown Source)
at java.lang.Thread.run(Unknown Source)
Caused by: java.lang.IllegalArgumentException: The JSON input text should neither be null nor empty.
at sun.reflect.NativeConstructorAccessorImpl.newInstance0(Native Method)
at sun.reflect.NativeConstructorAccessorImpl.newInstance(Unknown Source)
at sun.reflect.DelegatingConstructorAccessorImpl.newInstance(Unknown Source)
at java.lang.reflect.Constructor.newInstance(Unknown Source)
at org.codehaus.groovy.reflection.CachedConstructor.invoke(CachedConstructor.java:72)
at org.codehaus.groovy.runtime.callsite.ConstructorSite$ConstructorSiteNoUnwrapNoCoerce.callConstructor(ConstructorSite.java:105)
at org.codehaus.groovy.runtime.callsite.CallSiteArray.defaultCallConstructor(CallSiteArray.java:59)
at org.codehaus.groovy.runtime.callsite.AbstractCallSite.callConstructor(AbstractCallSite.java:263)
at org.codehaus.groovy.runtime.callsite.AbstractCallSite.callConstructor(AbstractCallSite.java:277)
at io.restassured.internal.path.json.ConfigurableJsonSlurper.parseText(ConfigurableJsonSlurper.groovy:80)
at io.restassured.path.json.JsonPath$4$1.method(JsonPath.java:965)
at io.restassured.path.json.JsonPath$ExceptionCatcher.invoke(JsonPath.java:1000)
... 17 more
]]>
            </full-stacktrace>
          </exception> <!-- io.restassured.path.json.exception.JsonPathException -->
          <reporter-output>
          </reporter-output>
        </test-method> <!-- checkResponseTime -->
        <test-method status="SKIP" signature="checkStatusCode()[pri:0, instance:com.employee.testCases.TC005_Delete_Employee_Record@4d1b0d2a]" name="checkStatusCode" duration-ms="0" started-at="2021-04-08T19:51:44 IST" finished-at="2021-04-08T19:51:44 IST">
          <exception class="io.restassured.path.json.exception.JsonPathException">
            <message>
              <![CDATA[Failed to parse the JSON document]]>
            </message>
            <full-stacktrace>
              <![CDATA[io.restassured.path.json.exception.JsonPathException: Failed to parse the JSON document
at io.restassured.path.json.JsonPath$ExceptionCatcher.invoke(JsonPath.java:1002)
at io.restassured.path.json.JsonPath$4.doParseWith(JsonPath.java:967)
at io.restassured.path.json.JsonPath$JsonParser.parseWith(JsonPath.java:1047)
at io.restassured.path.json.JsonPath.get(JsonPath.java:202)
at com.employee.testCases.TC005_Delete_Employee_Record.getAllEmployees(TC005_Delete_Employee_Record.java:28)
at sun.reflect.NativeMethodAccessorImpl.invoke0(Native Method)
at sun.reflect.NativeMethodAccessorImpl.invoke(Unknown Source)
at sun.reflect.DelegatingMethodAccessorImpl.invoke(Unknown Source)
at java.lang.reflect.Method.invoke(Unknown Source)
at org.testng.internal.MethodInvocationHelper.invokeMethod(MethodInvocationHelper.java:133)
at org.testng.internal.MethodInvocationHelper.invokeMethodConsideringTimeout(MethodInvocationHelper.java:62)
at org.testng.internal.ConfigInvoker.invokeConfigurationMethod(ConfigInvoker.java:385)
at org.testng.internal.ConfigInvoker.invokeConfigurations(ConfigInvoker.java:321)
at org.testng.internal.TestMethodWorker.invokeBeforeClassMethods(TestMethodWorker.java:176)
at org.testng.internal.TestMethodWorker.run(TestMethodWorker.java:122)
at java.util.concurrent.ThreadPoolExecutor.runWorker(Unknown Source)
at java.util.concurrent.ThreadPoolExecutor$Worker.run(Unknown Source)
at java.lang.Thread.run(Unknown Source)
Caused by: java.lang.IllegalArgumentException: The JSON input text should neither be null nor empty.
at sun.reflect.NativeConstructorAccessorImpl.newInstance0(Native Method)
at sun.reflect.NativeConstructorAccessorImpl.newInstance(Unknown Source)
at sun.reflect.DelegatingConstructorAccessorImpl.newInstance(Unknown Source)
at java.lang.reflect.Constructor.newInstance(Unknown Source)
at org.codehaus.groovy.reflection.CachedConstructor.invoke(CachedConstructor.java:72)
at org.codehaus.groovy.runtime.callsite.ConstructorSite$ConstructorSiteNoUnwrapNoCoerce.callConstructor(ConstructorSite.java:105)
at org.codehaus.groovy.runtime.callsite.CallSiteArray.defaultCallConstructor(CallSiteArray.java:59)
at org.codehaus.groovy.runtime.callsite.AbstractCallSite.callConstructor(AbstractCallSite.java:263)
at org.codehaus.groovy.runtime.callsite.AbstractCallSite.callConstructor(AbstractCallSite.java:277)
at io.restassured.internal.path.json.ConfigurableJsonSlurper.parseText(ConfigurableJsonSlurper.groovy:80)
at io.restassured.path.json.JsonPath$4$1.method(JsonPath.java:965)
at io.restassured.path.json.JsonPath$ExceptionCatcher.invoke(JsonPath.java:1000)
... 17 more
]]>
            </full-stacktrace>
          </exception> <!-- io.restassured.path.json.exception.JsonPathException -->
          <reporter-output>
          </reporter-output>
        </test-method> <!-- checkStatusCode -->
        <test-method status="SKIP" signature="checkstatusLine()[pri:0, instance:com.employee.testCases.TC005_Delete_Employee_Record@4d1b0d2a]" name="checkstatusLine" duration-ms="0" started-at="2021-04-08T19:51:44 IST" finished-at="2021-04-08T19:51:44 IST">
          <exception class="io.restassured.path.json.exception.JsonPathException">
            <message>
              <![CDATA[Failed to parse the JSON document]]>
            </message>
            <full-stacktrace>
              <![CDATA[io.restassured.path.json.exception.JsonPathException: Failed to parse the JSON document
at io.restassured.path.json.JsonPath$ExceptionCatcher.invoke(JsonPath.java:1002)
at io.restassured.path.json.JsonPath$4.doParseWith(JsonPath.java:967)
at io.restassured.path.json.JsonPath$JsonParser.parseWith(JsonPath.java:1047)
at io.restassured.path.json.JsonPath.get(JsonPath.java:202)
at com.employee.testCases.TC005_Delete_Employee_Record.getAllEmployees(TC005_Delete_Employee_Record.java:28)
at sun.reflect.NativeMethodAccessorImpl.invoke0(Native Method)
at sun.reflect.NativeMethodAccessorImpl.invoke(Unknown Source)
at sun.reflect.DelegatingMethodAccessorImpl.invoke(Unknown Source)
at java.lang.reflect.Method.invoke(Unknown Source)
at org.testng.internal.MethodInvocationHelper.invokeMethod(MethodInvocationHelper.java:133)
at org.testng.internal.MethodInvocationHelper.invokeMethodConsideringTimeout(MethodInvocationHelper.java:62)
at org.testng.internal.ConfigInvoker.invokeConfigurationMethod(ConfigInvoker.java:385)
at org.testng.internal.ConfigInvoker.invokeConfigurations(ConfigInvoker.java:321)
at org.testng.internal.TestMethodWorker.invokeBeforeClassMethods(TestMethodWorker.java:176)
at org.testng.internal.TestMethodWorker.run(TestMethodWorker.java:122)
at java.util.concurrent.ThreadPoolExecutor.runWorker(Unknown Source)
at java.util.concurrent.ThreadPoolExecutor$Worker.run(Unknown Source)
at java.lang.Thread.run(Unknown Source)
Caused by: java.lang.IllegalArgumentException: The JSON input text should neither be null nor empty.
at sun.reflect.NativeConstructorAccessorImpl.newInstance0(Native Method)
at sun.reflect.NativeConstructorAccessorImpl.newInstance(Unknown Source)
at sun.reflect.DelegatingConstructorAccessorImpl.newInstance(Unknown Source)
at java.lang.reflect.Constructor.newInstance(Unknown Source)
at org.codehaus.groovy.reflection.CachedConstructor.invoke(CachedConstructor.java:72)
at org.codehaus.groovy.runtime.callsite.ConstructorSite$ConstructorSiteNoUnwrapNoCoerce.callConstructor(ConstructorSite.java:105)
at org.codehaus.groovy.runtime.callsite.CallSiteArray.defaultCallConstructor(CallSiteArray.java:59)
at org.codehaus.groovy.runtime.callsite.AbstractCallSite.callConstructor(AbstractCallSite.java:263)
at org.codehaus.groovy.runtime.callsite.AbstractCallSite.callConstructor(AbstractCallSite.java:277)
at io.restassured.internal.path.json.ConfigurableJsonSlurper.parseText(ConfigurableJsonSlurper.groovy:80)
at io.restassured.path.json.JsonPath$4$1.method(JsonPath.java:965)
at io.restassured.path.json.JsonPath$ExceptionCatcher.invoke(JsonPath.java:1000)
... 17 more
]]>
            </full-stacktrace>
          </exception> <!-- io.restassured.path.json.exception.JsonPathException -->
          <reporter-output>
          </reporter-output>
        </test-method> <!-- checkstatusLine -->
        <test-method status="SKIP" signature="tearDown()[pri:0, instance:com.employee.testCases.TC005_Delete_Employee_Record@4d1b0d2a]" name="tearDown" is-config="true" duration-ms="-1617891704619" started-at="2021-04-08T19:51:44 IST" finished-at="1970-01-01T05:30:00 IST">
          <reporter-output>
          </reporter-output>
        </test-method> <!-- tearDown -->
      </class> <!-- com.employee.testCases.TC005_Delete_Employee_Record -->
      <class name="com.employee.testCases.TC001_Get_All_Employees">
        <test-method status="PASS" signature="setUp()[pri:0, instance:com.employee.testCases.TC001_Get_All_Employees@7276c8cd]" name="setUp" is-config="true" duration-ms="37" started-at="2021-04-08T19:51:40 IST" finished-at="2021-04-08T19:51:40 IST">
          <reporter-output>
          </reporter-output>
        </test-method> <!-- setUp -->
        <test-method status="PASS" signature="getAllEmployees()[pri:0, instance:com.employee.testCases.TC001_Get_All_Employees@7276c8cd]" name="getAllEmployees" is-config="true" duration-ms="4590" started-at="2021-04-08T19:51:40 IST" finished-at="2021-04-08T19:51:45 IST">
          <reporter-output>
          </reporter-output>
        </test-method> <!-- getAllEmployees -->
        <test-method status="PASS" signature="checkResponseBody()[pri:0, instance:com.employee.testCases.TC001_Get_All_Employees@7276c8cd]" name="checkResponseBody" duration-ms="32" started-at="2021-04-08T19:51:45 IST" finished-at="2021-04-08T19:51:45 IST">
          <reporter-output>
          </reporter-output>
        </test-method> <!-- checkResponseBody -->
        <test-method status="PASS" signature="checkResponseTime()[pri:0, instance:com.employee.testCases.TC001_Get_All_Employees@7276c8cd]" name="checkResponseTime" duration-ms="2" started-at="2021-04-08T19:51:45 IST" finished-at="2021-04-08T19:51:45 IST">
          <reporter-output>
          </reporter-output>
        </test-method> <!-- checkResponseTime -->
        <test-method status="FAIL" signature="checkStatusCode()[pri:0, instance:com.employee.testCases.TC001_Get_All_Employees@7276c8cd]" name="checkStatusCode" duration-ms="7" started-at="2021-04-08T19:51:45 IST" finished-at="2021-04-08T19:51:45 IST">
          <exception class="java.lang.AssertionError">
            <message>
              <![CDATA[expected [200] but found [429]]]>
            </message>
            <full-stacktrace>
              <![CDATA[java.lang.AssertionError: expected [200] but found [429]
at org.testng.Assert.fail(Assert.java:99)
at org.testng.Assert.failNotEquals(Assert.java:1037)
at org.testng.Assert.assertEqualsImpl(Assert.java:140)
at org.testng.Assert.assertEquals(Assert.java:122)
at org.testng.Assert.assertEquals(Assert.java:907)
at org.testng.Assert.assertEquals(Assert.java:917)
at com.employee.testCases.TC001_Get_All_Employees.checkStatusCode(TC001_Get_All_Employees.java:45)
at sun.reflect.NativeMethodAccessorImpl.invoke0(Native Method)
at sun.reflect.NativeMethodAccessorImpl.invoke(Unknown Source)
at sun.reflect.DelegatingMethodAccessorImpl.invoke(Unknown Source)
at java.lang.reflect.Method.invoke(Unknown Source)
at org.testng.internal.MethodInvocationHelper.invokeMethod(MethodInvocationHelper.java:133)
at org.testng.internal.TestInvoker.invokeMethod(TestInvoker.java:598)
at org.testng.internal.TestInvoker.invokeTestMethod(TestInvoker.java:173)
at org.testng.internal.MethodRunner.runInSequence(MethodRunner.java:46)
at org.testng.internal.TestInvoker$MethodInvocationAgent.invoke(TestInvoker.java:824)
at org.testng.internal.TestInvoker.invokeTestMethods(TestInvoker.java:146)
at org.testng.internal.TestMethodWorker.invokeTestMethods(TestMethodWorker.java:146)
at org.testng.internal.TestMethodWorker.run(TestMethodWorker.java:128)
at java.util.concurrent.ThreadPoolExecutor.runWorker(Unknown Source)
at java.util.concurrent.ThreadPoolExecutor$Worker.run(Unknown Source)
at java.lang.Thread.run(Unknown Source)
]]>
            </full-stacktrace>
          </exception> <!-- java.lang.AssertionError -->
          <reporter-output>
          </reporter-output>
        </test-method> <!-- checkStatusCode -->
        <test-method status="FAIL" signature="checkstatusLine()[pri:0, instance:com.employee.testCases.TC001_Get_All_Employees@7276c8cd]" name="checkstatusLine" duration-ms="2" started-at="2021-04-08T19:51:45 IST" finished-at="2021-04-08T19:51:45 IST">
          <exception class="java.lang.AssertionError">
            <message>
              <![CDATA[expected [HTTP/1.1 200 OK] but found [HTTP/1.1 429 Too Many Requests]]]>
            </message>
            <full-stacktrace>
              <![CDATA[java.lang.AssertionError: expected [HTTP/1.1 200 OK] but found [HTTP/1.1 429 Too Many Requests]
at org.testng.Assert.fail(Assert.java:99)
at org.testng.Assert.failNotEquals(Assert.java:1037)
at org.testng.Assert.assertEqualsImpl(Assert.java:140)
at org.testng.Assert.assertEquals(Assert.java:122)
at org.testng.Assert.assertEquals(Assert.java:629)
at org.testng.Assert.assertEquals(Assert.java:639)
at com.employee.testCases.TC001_Get_All_Employees.checkstatusLine(TC001_Get_All_Employees.java:67)
at sun.reflect.NativeMethodAccessorImpl.invoke0(Native Method)
at sun.reflect.NativeMethodAccessorImpl.invoke(Unknown Source)
at sun.reflect.DelegatingMethodAccessorImpl.invoke(Unknown Source)
at java.lang.reflect.Method.invoke(Unknown Source)
at org.testng.internal.MethodInvocationHelper.invokeMethod(MethodInvocationHelper.java:133)
at org.testng.internal.TestInvoker.invokeMethod(TestInvoker.java:598)
at org.testng.internal.TestInvoker.invokeTestMethod(TestInvoker.java:173)
at org.testng.internal.MethodRunner.runInSequence(MethodRunner.java:46)
at org.testng.internal.TestInvoker$MethodInvocationAgent.invoke(TestInvoker.java:824)
at org.testng.internal.TestInvoker.invokeTestMethods(TestInvoker.java:146)
at org.testng.internal.TestMethodWorker.invokeTestMethods(TestMethodWorker.java:146)
at org.testng.internal.TestMethodWorker.run(TestMethodWorker.java:128)
at java.util.concurrent.ThreadPoolExecutor.runWorker(Unknown Source)
at java.util.concurrent.ThreadPoolExecutor$Worker.run(Unknown Source)
at java.lang.Thread.run(Unknown Source)
]]>
            </full-stacktrace>
          </exception> <!-- java.lang.AssertionError -->
          <reporter-output>
          </reporter-output>
        </test-method> <!-- checkstatusLine -->
        <test-method status="PASS" signature="tearDown()[pri:0, instance:com.employee.testCases.TC001_Get_All_Employees@7276c8cd]" name="tearDown" is-config="true" duration-ms="1" started-at="2021-04-08T19:51:45 IST" finished-at="2021-04-08T19:51:45 IST">
          <reporter-output>
          </reporter-output>
        </test-method> <!-- tearDown -->
      </class> <!-- com.employee.testCases.TC001_Get_All_Employees -->
      <class name="com.employee.testCases.TC003_Post_Employee_Record">
        <test-method status="PASS" signature="setUp()[pri:0, instance:com.employee.testCases.TC003_Post_Employee_Record@10a035a0]" name="setUp" is-config="true" duration-ms="38" started-at="2021-04-08T19:51:40 IST" finished-at="2021-04-08T19:51:40 IST">
          <reporter-output>
          </reporter-output>
        </test-method> <!-- setUp -->
        <test-method status="PASS" signature="getAllEmployees()[pri:0, instance:com.employee.testCases.TC003_Post_Employee_Record@10a035a0]" name="getAllEmployees" is-config="true" duration-ms="9883" started-at="2021-04-08T19:51:40 IST" finished-at="2021-04-08T19:51:50 IST">
          <reporter-output>
          </reporter-output>
        </test-method> <!-- getAllEmployees -->
        <test-method status="FAIL" signature="checkContentType()[pri:0, instance:com.employee.testCases.TC003_Post_Employee_Record@10a035a0]" name="checkContentType" duration-ms="1" started-at="2021-04-08T19:51:50 IST" finished-at="2021-04-08T19:51:50 IST">
          <exception class="java.lang.AssertionError">
            <message>
              <![CDATA[expected [application/json] but found [text/html; charset=UTF-8]]]>
            </message>
            <full-stacktrace>
              <![CDATA[java.lang.AssertionError: expected [application/json] but found [text/html; charset=UTF-8]
at org.testng.Assert.fail(Assert.java:99)
at org.testng.Assert.failNotEquals(Assert.java:1037)
at org.testng.Assert.assertEqualsImpl(Assert.java:140)
at org.testng.Assert.assertEquals(Assert.java:122)
at org.testng.Assert.assertEquals(Assert.java:629)
at org.testng.Assert.assertEquals(Assert.java:639)
at com.employee.testCases.TC003_Post_Employee_Record.checkContentType(TC003_Post_Employee_Record.java:94)
at sun.reflect.NativeMethodAccessorImpl.invoke0(Native Method)
at sun.reflect.NativeMethodAccessorImpl.invoke(Unknown Source)
at sun.reflect.DelegatingMethodAccessorImpl.invoke(Unknown Source)
at java.lang.reflect.Method.invoke(Unknown Source)
at org.testng.internal.MethodInvocationHelper.invokeMethod(MethodInvocationHelper.java:133)
at org.testng.internal.TestInvoker.invokeMethod(TestInvoker.java:598)
at org.testng.internal.TestInvoker.invokeTestMethod(TestInvoker.java:173)
at org.testng.internal.MethodRunner.runInSequence(MethodRunner.java:46)
at org.testng.internal.TestInvoker$MethodInvocationAgent.invoke(TestInvoker.java:824)
at org.testng.internal.TestInvoker.invokeTestMethods(TestInvoker.java:146)
at org.testng.internal.TestMethodWorker.invokeTestMethods(TestMethodWorker.java:146)
at org.testng.internal.TestMethodWorker.run(TestMethodWorker.java:128)
at java.util.concurrent.ThreadPoolExecutor.runWorker(Unknown Source)
at java.util.concurrent.ThreadPoolExecutor$Worker.run(Unknown Source)
at java.lang.Thread.run(Unknown Source)
]]>
            </full-stacktrace>
          </exception> <!-- java.lang.AssertionError -->
          <reporter-output>
          </reporter-output>
        </test-method> <!-- checkContentType -->
        <test-method status="FAIL" signature="checkResponseBody()[pri:0, instance:com.employee.testCases.TC003_Post_Employee_Record@10a035a0]" name="checkResponseBody" duration-ms="1" started-at="2021-04-08T19:51:50 IST" finished-at="2021-04-08T19:51:50 IST">
          <exception class="java.lang.AssertionError">
            <message>
              <![CDATA[expected [true] but found [false]]]>
            </message>
            <full-stacktrace>
              <![CDATA[java.lang.AssertionError: expected [true] but found [false]
at org.testng.Assert.fail(Assert.java:99)
at org.testng.Assert.failNotEquals(Assert.java:1037)
at org.testng.Assert.assertTrue(Assert.java:45)
at org.testng.Assert.assertTrue(Assert.java:55)
at com.employee.testCases.TC003_Post_Employee_Record.checkResponseBody(TC003_Post_Employee_Record.java:51)
at sun.reflect.NativeMethodAccessorImpl.invoke0(Native Method)
at sun.reflect.NativeMethodAccessorImpl.invoke(Unknown Source)
at sun.reflect.DelegatingMethodAccessorImpl.invoke(Unknown Source)
at java.lang.reflect.Method.invoke(Unknown Source)
at org.testng.internal.MethodInvocationHelper.invokeMethod(MethodInvocationHelper.java:133)
at org.testng.internal.TestInvoker.invokeMethod(TestInvoker.java:598)
at org.testng.internal.TestInvoker.invokeTestMethod(TestInvoker.java:173)
at org.testng.internal.MethodRunner.runInSequence(MethodRunner.java:46)
at org.testng.internal.TestInvoker$MethodInvocationAgent.invoke(TestInvoker.java:824)
at org.testng.internal.TestInvoker.invokeTestMethods(TestInvoker.java:146)
at org.testng.internal.TestMethodWorker.invokeTestMethods(TestMethodWorker.java:146)
at org.testng.internal.TestMethodWorker.run(TestMethodWorker.java:128)
at java.util.concurrent.ThreadPoolExecutor.runWorker(Unknown Source)
at java.util.concurrent.ThreadPoolExecutor$Worker.run(Unknown Source)
at java.lang.Thread.run(Unknown Source)
]]>
            </full-stacktrace>
          </exception> <!-- java.lang.AssertionError -->
          <reporter-output>
          </reporter-output>
        </test-method> <!-- checkResponseBody -->
        <test-method status="PASS" signature="checkResponseTime()[pri:0, instance:com.employee.testCases.TC003_Post_Employee_Record@10a035a0]" name="checkResponseTime" duration-ms="0" started-at="2021-04-08T19:51:50 IST" finished-at="2021-04-08T19:51:50 IST">
          <reporter-output>
          </reporter-output>
        </test-method> <!-- checkResponseTime -->
        <test-method status="FAIL" signature="checkStatusCode()[pri:0, instance:com.employee.testCases.TC003_Post_Employee_Record@10a035a0]" name="checkStatusCode" duration-ms="1" started-at="2021-04-08T19:51:50 IST" finished-at="2021-04-08T19:51:50 IST">
          <exception class="java.lang.AssertionError">
            <message>
              <![CDATA[expected [200] but found [405]]]>
            </message>
            <full-stacktrace>
              <![CDATA[java.lang.AssertionError: expected [200] but found [405]
at org.testng.Assert.fail(Assert.java:99)
at org.testng.Assert.failNotEquals(Assert.java:1037)
at org.testng.Assert.assertEqualsImpl(Assert.java:140)
at org.testng.Assert.assertEquals(Assert.java:122)
at org.testng.Assert.assertEquals(Assert.java:907)
at org.testng.Assert.assertEquals(Assert.java:917)
at com.employee.testCases.TC003_Post_Employee_Record.checkStatusCode(TC003_Post_Employee_Record.java:64)
at sun.reflect.NativeMethodAccessorImpl.invoke0(Native Method)
at sun.reflect.NativeMethodAccessorImpl.invoke(Unknown Source)
at sun.reflect.DelegatingMethodAccessorImpl.invoke(Unknown Source)
at java.lang.reflect.Method.invoke(Unknown Source)
at org.testng.internal.MethodInvocationHelper.invokeMethod(MethodInvocationHelper.java:133)
at org.testng.internal.TestInvoker.invokeMethod(TestInvoker.java:598)
at org.testng.internal.TestInvoker.invokeTestMethod(TestInvoker.java:173)
at org.testng.internal.MethodRunner.runInSequence(MethodRunner.java:46)
at org.testng.internal.TestInvoker$MethodInvocationAgent.invoke(TestInvoker.java:824)
at org.testng.internal.TestInvoker.invokeTestMethods(TestInvoker.java:146)
at org.testng.internal.TestMethodWorker.invokeTestMethods(TestMethodWorker.java:146)
at org.testng.internal.TestMethodWorker.run(TestMethodWorker.java:128)
at java.util.concurrent.ThreadPoolExecutor.runWorker(Unknown Source)
at java.util.concurrent.ThreadPoolExecutor$Worker.run(Unknown Source)
at java.lang.Thread.run(Unknown Source)
]]>
            </full-stacktrace>
          </exception> <!-- java.lang.AssertionError -->
          <reporter-output>
          </reporter-output>
        </test-method> <!-- checkStatusCode -->
        <test-method status="FAIL" signature="checkstatusLine()[pri:0, instance:com.employee.testCases.TC003_Post_Employee_Record@10a035a0]" name="checkstatusLine" duration-ms="1" started-at="2021-04-08T19:51:50 IST" finished-at="2021-04-08T19:51:50 IST">
          <exception class="java.lang.AssertionError">
            <message>
              <![CDATA[expected [HTTP/1.1 200 OK] but found [HTTP/1.1 405 Method Not Allowed]]]>
            </message>
            <full-stacktrace>
              <![CDATA[java.lang.AssertionError: expected [HTTP/1.1 200 OK] but found [HTTP/1.1 405 Method Not Allowed]
at org.testng.Assert.fail(Assert.java:99)
at org.testng.Assert.failNotEquals(Assert.java:1037)
at org.testng.Assert.assertEqualsImpl(Assert.java:140)
at org.testng.Assert.assertEquals(Assert.java:122)
at org.testng.Assert.assertEquals(Assert.java:629)
at org.testng.Assert.assertEquals(Assert.java:639)
at com.employee.testCases.TC003_Post_Employee_Record.checkstatusLine(TC003_Post_Employee_Record.java:86)
at sun.reflect.NativeMethodAccessorImpl.invoke0(Native Method)
at sun.reflect.NativeMethodAccessorImpl.invoke(Unknown Source)
at sun.reflect.DelegatingMethodAccessorImpl.invoke(Unknown Source)
at java.lang.reflect.Method.invoke(Unknown Source)
at org.testng.internal.MethodInvocationHelper.invokeMethod(MethodInvocationHelper.java:133)
at org.testng.internal.TestInvoker.invokeMethod(TestInvoker.java:598)
at org.testng.internal.TestInvoker.invokeTestMethod(TestInvoker.java:173)
at org.testng.internal.MethodRunner.runInSequence(MethodRunner.java:46)
at org.testng.internal.TestInvoker$MethodInvocationAgent.invoke(TestInvoker.java:824)
at org.testng.internal.TestInvoker.invokeTestMethods(TestInvoker.java:146)
at org.testng.internal.TestMethodWorker.invokeTestMethods(TestMethodWorker.java:146)
at org.testng.internal.TestMethodWorker.run(TestMethodWorker.java:128)
at java.util.concurrent.ThreadPoolExecutor.runWorker(Unknown Source)
at java.util.concurrent.ThreadPoolExecutor$Worker.run(Unknown Source)
at java.lang.Thread.run(Unknown Source)
]]>
            </full-stacktrace>
          </exception> <!-- java.lang.AssertionError -->
          <reporter-output>
          </reporter-output>
        </test-method> <!-- checkstatusLine -->
        <test-method status="PASS" signature="tearDown()[pri:0, instance:com.employee.testCases.TC003_Post_Employee_Record@10a035a0]" name="tearDown" is-config="true" duration-ms="1" started-at="2021-04-08T19:51:50 IST" finished-at="2021-04-08T19:51:50 IST">
          <reporter-output>
          </reporter-output>
        </test-method> <!-- tearDown -->
      </class> <!-- com.employee.testCases.TC003_Post_Employee_Record -->
      <class name="com.employee.testCases.TC004_Put_Employee_Record">
        <test-method status="PASS" signature="setUp()[pri:0, instance:com.employee.testCases.TC004_Put_Employee_Record@47db50c5]" name="setUp" is-config="true" duration-ms="36" started-at="2021-04-08T19:51:40 IST" finished-at="2021-04-08T19:51:40 IST">
          <reporter-output>
          </reporter-output>
        </test-method> <!-- setUp -->
        <test-method status="PASS" signature="getAllEmployees()[pri:0, instance:com.employee.testCases.TC004_Put_Employee_Record@47db50c5]" name="getAllEmployees" is-config="true" duration-ms="7003" started-at="2021-04-08T19:51:40 IST" finished-at="2021-04-08T19:51:47 IST">
          <reporter-output>
          </reporter-output>
        </test-method> <!-- getAllEmployees -->
        <test-method status="FAIL" signature="checkContentType()[pri:0, instance:com.employee.testCases.TC004_Put_Employee_Record@47db50c5]" name="checkContentType" duration-ms="5" started-at="2021-04-08T19:51:47 IST" finished-at="2021-04-08T19:51:47 IST">
          <exception class="java.lang.AssertionError">
            <message>
              <![CDATA[expected [application/json] but found [text/html; charset=UTF-8]]]>
            </message>
            <full-stacktrace>
              <![CDATA[java.lang.AssertionError: expected [application/json] but found [text/html; charset=UTF-8]
at org.testng.Assert.fail(Assert.java:99)
at org.testng.Assert.failNotEquals(Assert.java:1037)
at org.testng.Assert.assertEqualsImpl(Assert.java:140)
at org.testng.Assert.assertEquals(Assert.java:122)
at org.testng.Assert.assertEquals(Assert.java:629)
at org.testng.Assert.assertEquals(Assert.java:639)
at com.employee.testCases.TC004_Put_Employee_Record.checkContentType(TC004_Put_Employee_Record.java:94)
at sun.reflect.NativeMethodAccessorImpl.invoke0(Native Method)
at sun.reflect.NativeMethodAccessorImpl.invoke(Unknown Source)
at sun.reflect.DelegatingMethodAccessorImpl.invoke(Unknown Source)
at java.lang.reflect.Method.invoke(Unknown Source)
at org.testng.internal.MethodInvocationHelper.invokeMethod(MethodInvocationHelper.java:133)
at org.testng.internal.TestInvoker.invokeMethod(TestInvoker.java:598)
at org.testng.internal.TestInvoker.invokeTestMethod(TestInvoker.java:173)
at org.testng.internal.MethodRunner.runInSequence(MethodRunner.java:46)
at org.testng.internal.TestInvoker$MethodInvocationAgent.invoke(TestInvoker.java:824)
at org.testng.internal.TestInvoker.invokeTestMethods(TestInvoker.java:146)
at org.testng.internal.TestMethodWorker.invokeTestMethods(TestMethodWorker.java:146)
at org.testng.internal.TestMethodWorker.run(TestMethodWorker.java:128)
at java.util.concurrent.ThreadPoolExecutor.runWorker(Unknown Source)
at java.util.concurrent.ThreadPoolExecutor$Worker.run(Unknown Source)
at java.lang.Thread.run(Unknown Source)
]]>
            </full-stacktrace>
          </exception> <!-- java.lang.AssertionError -->
          <reporter-output>
          </reporter-output>
        </test-method> <!-- checkContentType -->
        <test-method status="FAIL" signature="checkResponseBody()[pri:0, instance:com.employee.testCases.TC004_Put_Employee_Record@47db50c5]" name="checkResponseBody" duration-ms="2" started-at="2021-04-08T19:51:47 IST" finished-at="2021-04-08T19:51:47 IST">
          <exception class="java.lang.AssertionError">
            <message>
              <![CDATA[expected [true] but found [false]]]>
            </message>
            <full-stacktrace>
              <![CDATA[java.lang.AssertionError: expected [true] but found [false]
at org.testng.Assert.fail(Assert.java:99)
at org.testng.Assert.failNotEquals(Assert.java:1037)
at org.testng.Assert.assertTrue(Assert.java:45)
at org.testng.Assert.assertTrue(Assert.java:55)
at com.employee.testCases.TC004_Put_Employee_Record.checkResponseBody(TC004_Put_Employee_Record.java:51)
at sun.reflect.NativeMethodAccessorImpl.invoke0(Native Method)
at sun.reflect.NativeMethodAccessorImpl.invoke(Unknown Source)
at sun.reflect.DelegatingMethodAccessorImpl.invoke(Unknown Source)
at java.lang.reflect.Method.invoke(Unknown Source)
at org.testng.internal.MethodInvocationHelper.invokeMethod(MethodInvocationHelper.java:133)
at org.testng.internal.TestInvoker.invokeMethod(TestInvoker.java:598)
at org.testng.internal.TestInvoker.invokeTestMethod(TestInvoker.java:173)
at org.testng.internal.MethodRunner.runInSequence(MethodRunner.java:46)
at org.testng.internal.TestInvoker$MethodInvocationAgent.invoke(TestInvoker.java:824)
at org.testng.internal.TestInvoker.invokeTestMethods(TestInvoker.java:146)
at org.testng.internal.TestMethodWorker.invokeTestMethods(TestMethodWorker.java:146)
at org.testng.internal.TestMethodWorker.run(TestMethodWorker.java:128)
at java.util.concurrent.ThreadPoolExecutor.runWorker(Unknown Source)
at java.util.concurrent.ThreadPoolExecutor$Worker.run(Unknown Source)
at java.lang.Thread.run(Unknown Source)
]]>
            </full-stacktrace>
          </exception> <!-- java.lang.AssertionError -->
          <reporter-output>
          </reporter-output>
        </test-method> <!-- checkResponseBody -->
        <test-method status="PASS" signature="checkResponseTime()[pri:0, instance:com.employee.testCases.TC004_Put_Employee_Record@47db50c5]" name="checkResponseTime" duration-ms="1" started-at="2021-04-08T19:51:47 IST" finished-at="2021-04-08T19:51:47 IST">
          <reporter-output>
          </reporter-output>
        </test-method> <!-- checkResponseTime -->
        <test-method status="FAIL" signature="checkStatusCode()[pri:0, instance:com.employee.testCases.TC004_Put_Employee_Record@47db50c5]" name="checkStatusCode" duration-ms="2" started-at="2021-04-08T19:51:47 IST" finished-at="2021-04-08T19:51:47 IST">
          <exception class="java.lang.AssertionError">
            <message>
              <![CDATA[expected [200] but found [405]]]>
            </message>
            <full-stacktrace>
              <![CDATA[java.lang.AssertionError: expected [200] but found [405]
at org.testng.Assert.fail(Assert.java:99)
at org.testng.Assert.failNotEquals(Assert.java:1037)
at org.testng.Assert.assertEqualsImpl(Assert.java:140)
at org.testng.Assert.assertEquals(Assert.java:122)
at org.testng.Assert.assertEquals(Assert.java:907)
at org.testng.Assert.assertEquals(Assert.java:917)
at com.employee.testCases.TC004_Put_Employee_Record.checkStatusCode(TC004_Put_Employee_Record.java:64)
at sun.reflect.NativeMethodAccessorImpl.invoke0(Native Method)
at sun.reflect.NativeMethodAccessorImpl.invoke(Unknown Source)
at sun.reflect.DelegatingMethodAccessorImpl.invoke(Unknown Source)
at java.lang.reflect.Method.invoke(Unknown Source)
at org.testng.internal.MethodInvocationHelper.invokeMethod(MethodInvocationHelper.java:133)
at org.testng.internal.TestInvoker.invokeMethod(TestInvoker.java:598)
at org.testng.internal.TestInvoker.invokeTestMethod(TestInvoker.java:173)
at org.testng.internal.MethodRunner.runInSequence(MethodRunner.java:46)
at org.testng.internal.TestInvoker$MethodInvocationAgent.invoke(TestInvoker.java:824)
at org.testng.internal.TestInvoker.invokeTestMethods(TestInvoker.java:146)
at org.testng.internal.TestMethodWorker.invokeTestMethods(TestMethodWorker.java:146)
at org.testng.internal.TestMethodWorker.run(TestMethodWorker.java:128)
at java.util.concurrent.ThreadPoolExecutor.runWorker(Unknown Source)
at java.util.concurrent.ThreadPoolExecutor$Worker.run(Unknown Source)
at java.lang.Thread.run(Unknown Source)
]]>
            </full-stacktrace>
          </exception> <!-- java.lang.AssertionError -->
          <reporter-output>
          </reporter-output>
        </test-method> <!-- checkStatusCode -->
        <test-method status="FAIL" signature="checkstatusLine()[pri:0, instance:com.employee.testCases.TC004_Put_Employee_Record@47db50c5]" name="checkstatusLine" duration-ms="1" started-at="2021-04-08T19:51:47 IST" finished-at="2021-04-08T19:51:47 IST">
          <exception class="java.lang.AssertionError">
            <message>
              <![CDATA[expected [HTTP/1.1 200 OK] but found [HTTP/1.1 405 Method Not Allowed]]]>
            </message>
            <full-stacktrace>
              <![CDATA[java.lang.AssertionError: expected [HTTP/1.1 200 OK] but found [HTTP/1.1 405 Method Not Allowed]
at org.testng.Assert.fail(Assert.java:99)
at org.testng.Assert.failNotEquals(Assert.java:1037)
at org.testng.Assert.assertEqualsImpl(Assert.java:140)
at org.testng.Assert.assertEquals(Assert.java:122)
at org.testng.Assert.assertEquals(Assert.java:629)
at org.testng.Assert.assertEquals(Assert.java:639)
at com.employee.testCases.TC004_Put_Employee_Record.checkstatusLine(TC004_Put_Employee_Record.java:86)
at sun.reflect.NativeMethodAccessorImpl.invoke0(Native Method)
at sun.reflect.NativeMethodAccessorImpl.invoke(Unknown Source)
at sun.reflect.DelegatingMethodAccessorImpl.invoke(Unknown Source)
at java.lang.reflect.Method.invoke(Unknown Source)
at org.testng.internal.MethodInvocationHelper.invokeMethod(MethodInvocationHelper.java:133)
at org.testng.internal.TestInvoker.invokeMethod(TestInvoker.java:598)
at org.testng.internal.TestInvoker.invokeTestMethod(TestInvoker.java:173)
at org.testng.internal.MethodRunner.runInSequence(MethodRunner.java:46)
at org.testng.internal.TestInvoker$MethodInvocationAgent.invoke(TestInvoker.java:824)
at org.testng.internal.TestInvoker.invokeTestMethods(TestInvoker.java:146)
at org.testng.internal.TestMethodWorker.invokeTestMethods(TestMethodWorker.java:146)
at org.testng.internal.TestMethodWorker.run(TestMethodWorker.java:128)
at java.util.concurrent.ThreadPoolExecutor.runWorker(Unknown Source)
at java.util.concurrent.ThreadPoolExecutor$Worker.run(Unknown Source)
at java.lang.Thread.run(Unknown Source)
]]>
            </full-stacktrace>
          </exception> <!-- java.lang.AssertionError -->
          <reporter-output>
          </reporter-output>
        </test-method> <!-- checkstatusLine -->
        <test-method status="PASS" signature="tearDown()[pri:0, instance:com.employee.testCases.TC004_Put_Employee_Record@47db50c5]" name="tearDown" is-config="true" duration-ms="0" started-at="2021-04-08T19:51:47 IST" finished-at="2021-04-08T19:51:47 IST">
          <reporter-output>
          </reporter-output>
        </test-method> <!-- tearDown -->
      </class> <!-- com.employee.testCases.TC004_Put_Employee_Record -->
      <class name="com.employee.testCases.TC002_Get_Single_Employee_Data">
        <test-method status="PASS" signature="setUp()[pri:0, instance:com.employee.testCases.TC002_Get_Single_Employee_Data@704d6e83]" name="setUp" is-config="true" duration-ms="39" started-at="2021-04-08T19:51:40 IST" finished-at="2021-04-08T19:51:40 IST">
          <reporter-output>
          </reporter-output>
        </test-method> <!-- setUp -->
        <test-method status="PASS" signature="getAllEmployees()[pri:0, instance:com.employee.testCases.TC002_Get_Single_Employee_Data@704d6e83]" name="getAllEmployees" is-config="true" duration-ms="4659" started-at="2021-04-08T19:51:40 IST" finished-at="2021-04-08T19:51:45 IST">
          <reporter-output>
          </reporter-output>
        </test-method> <!-- getAllEmployees -->
        <test-method status="PASS" signature="checkContentType()[pri:0, instance:com.employee.testCases.TC002_Get_Single_Employee_Data@704d6e83]" name="checkContentType" duration-ms="1" started-at="2021-04-08T19:51:45 IST" finished-at="2021-04-08T19:51:45 IST">
          <reporter-output>
          </reporter-output>
        </test-method> <!-- checkContentType -->
        <test-method status="PASS" signature="checkResponseBody()[pri:0, instance:com.employee.testCases.TC002_Get_Single_Employee_Data@704d6e83]" name="checkResponseBody" duration-ms="2" started-at="2021-04-08T19:51:45 IST" finished-at="2021-04-08T19:51:45 IST">
          <reporter-output>
          </reporter-output>
        </test-method> <!-- checkResponseBody -->
        <test-method status="PASS" signature="checkResponseTime()[pri:0, instance:com.employee.testCases.TC002_Get_Single_Employee_Data@704d6e83]" name="checkResponseTime" duration-ms="1" started-at="2021-04-08T19:51:45 IST" finished-at="2021-04-08T19:51:45 IST">
          <reporter-output>
          </reporter-output>
        </test-method> <!-- checkResponseTime -->
        <test-method status="PASS" signature="checkStatusCode()[pri:0, instance:com.employee.testCases.TC002_Get_Single_Employee_Data@704d6e83]" name="checkStatusCode" duration-ms="2" started-at="2021-04-08T19:51:45 IST" finished-at="2021-04-08T19:51:45 IST">
          <reporter-output>
          </reporter-output>
        </test-method> <!-- checkStatusCode -->
        <test-method status="PASS" signature="checkstatusLine()[pri:0, instance:com.employee.testCases.TC002_Get_Single_Employee_Data@704d6e83]" name="checkstatusLine" duration-ms="1" started-at="2021-04-08T19:51:45 IST" finished-at="2021-04-08T19:51:45 IST">
          <reporter-output>
          </reporter-output>
        </test-method> <!-- checkstatusLine -->
        <test-method status="PASS" signature="tearDown()[pri:0, instance:com.employee.testCases.TC002_Get_Single_Employee_Data@704d6e83]" name="tearDown" is-config="true" duration-ms="0" started-at="2021-04-08T19:51:45 IST" finished-at="2021-04-08T19:51:45 IST">
          <reporter-output>
          </reporter-output>
        </test-method> <!-- tearDown -->
      </class> <!-- com.employee.testCases.TC002_Get_Single_Employee_Data -->
    </test> <!-- restassuredtests -->
  </suite> <!-- restassuredtestsuite -->
</testng-results>
